# GO语言异常处理

## error

### errors接口

```django
type error interface {
	Error() string
}
```

`error`本质是一个接口类型，其中包含一个`Error()`方法，错误值可以存储在变量中，通过函数返回。它必须是函数返回的最后一个值

Go语言中处理错误的方法通常是返回错误与`nil`进行比较，`nil`值表示没有错误发生，非nil值表示出现错误。如果不是`nil`需打印输出错误。

示例：

```go
package main

import (
	"errors"
	"fmt"
	"math"
	"os"
)
// 运算平方根函数
func mySqrt(f float64)(float64,error){
	if f<0{
		return 0, errors.New("负数不可以求平方根")
	}
	return math.Sqrt(f),nil
}

// 定义出发运算函数
func Divide(divedee float64,divider float64)(float64,error){
	if divider == 0{
		return 0,errors.New("除数不可以为0！")
	}
	return divedee / divider , nil
}

func main() {
	// 异常1
	res := math.Sqrt(-100)     // 求平方根
	fmt.Println(res)
	res , err := mySqrt(-100)  // 调用自定义函数
	// 判断返回值错误
	if err != nil{
		fmt.Println(err)
	} else {
		fmt.Println(res)
	}

	// 异常2
	res2,err := Divide(100,0)
	if err != nil{
		fmt.Println(err.Error()) // 除数不可以为0！
		fmt.Println(err)         // 同上   除数不可以为0！
	}else {
		fmt.Println(res2)
	}

	// 异常3
	f ,err := os.Open("abc.txt")
	if err != nil{
		fmt.Println(err)
		return
	}
	fmt.Println(f.Name())
}
```

### 创建error对象

结构体只要实现了`Error()sting`这种格式的方法，就代表实现了该错误接口，返回值为错误的具体描述。通常程序会发生可预知的错误，所以Go语言errors包对外提供了可供用户自定义的方法，errors包下的`New`函数返回`error对象`，`errors.New()`函数创建新的错误

 ```go
package errors

// New returns an error that formats as the given text.
// Each call to New returns a distinct error value even if the text is identical.
func New(text string) error {
	return &errorString{text}
}

// errorString is a trivial implementation of error.
type errorString struct {
	s string
}

func (e *errorString) Error() string {
	return e.s
}
 ```

示例：

```go
package main

import (
	"errors"
	"fmt"
)

func main() {
	// 创建error对象的方式1
	err1 := errors.New("my error1")
	fmt.Println(err1.Error())            // my error1
	fmt.Println(err1)                    // my error1
	fmt.Printf("%T\n",err1)         // *errors.errorString

	// 创建error对象2
	err2 := fmt.Errorf("my error2")
	fmt.Println(err2.Error())            // my error2
	fmt.Println(err2)                    // my error2
	fmt.Printf("%T\n",err2)       // *errors.errorString

	// error对象在函数中使用
	f := func (tel uint32)(uint32 ,error){
		if len(string(tel)) < 11{
			err := fmt.Errorf("%v太短了",tel)
			return 0,err
		}
		return tel,nil
	}
	tel,err3 := f(12345678)
	if err3 != nil{
		fmt.Println(err3)
		return
	}
	fmt.Println(tel)  // 12345678太短了
}
```



### 自定义错误

自定义错误步骤：

1. 定义一个结构体，表示自定义错误的类型。

2. 让自定义错误类型实现error接口：`Error()string`
3. 定义一个返回error的函数

示例：

```go
package main

import (
	"fmt"
	"time"
)

// 定义结构体，表示自定义错误类型
type MyError struct {
	When string
	What string
}
// 实现Error()方法
func (M MyError) Error() string{
	return fmt.Sprintf("%v: %v",M.When,M.What)
}
// 定义一个返回error的函数
func getArea(width,length float64) (float64,error){
	errorInfo := ""
	if width < 0 && length < 0{
		errorInfo = fmt.Sprintf("长%v 宽%v，均为负数",length,width)
	} else if length < 0{
		errorInfo = fmt.Sprintf("长%v 为负数",length)
	} else if width  < 0 {
		errorInfo = fmt.Sprintf("宽%v 为负数",width)
	}
	if errorInfo != ""{
		return 0,MyError{time.Now().Format("2006-01-02 15:04:05"),errorInfo}
	}else {
		return width * length,nil
	}
}

func main() {
	res,err := getArea(-2,-5)
	if err != nil{
		fmt.Printf(err.Error())
		return
	}
	fmt.Println("面积是：",res)
}
```



## panic和recover机制

### panic

`panic`,让当前程序进入恐慌，中断程序执行。`panic()`事一个内建函数，可以中断原有的控制流程。

```go
func main() {
	fmt.Println(1)  // 1
	fmt.Println(2)  // 2
	panic("中断")   
	fmt.Println(3)
}
/*
1
2
panic: 中断

goroutine 1 [running]:
main.main()
	C:/Users/Administrator/go/src/awesomeProject/mtest/main.go:8 +0xd9
*/
```

当遇到不可恢复的错误状态时，如数组越界、空指针引用等，这些运行事错误会引起panic异常

```go
func main() {
	fmt.Println(1)
	fmt.Println(2)
	var v1 [2]int
	v1[3] = 2
	fmt.Println(v1)
}
/*
# awesomeProject/mtest
.\main.go:9:4: invalid array index 3 (out of bounds for 2-element array)
*/
```

### recover

`panic`异常会导致程序崩溃，Go语言为开发提供了专用与拦截运行时`panic`的内建函数`recover()`.

`recover()`可以让进入恐慌流程`goroutine`恢复过来并重新获得流程控制权。

`recover()`让程序恢复，不许再延迟函数中执行。

在正常程序运行过程中，调用`recover()`会返回`nil`，并且没有其他任何效果。如果`goroutine`在恐慌状态，调用`recover()`可以捕获`panic()`的输入值，使程序恢复正常。

```GO
package main

import "fmt"

func testa() {
	fmt.Println("aaaaaaaaaaaaaaaaa")
}

func testb(x int) {
	//设置recover，recover只能放在defer后面使用
	defer func() {
		//recover() //可以打印panic的错误信息
		//fmt.Println(recover())
		if err := recover(); err != nil { //产生了panic异常
			fmt.Println(err)
		}

	}() //别忘了(), 调用此匿名函数

	var a [10]int
	a[x] = 111 //当x为20时候，导致数组越界，产生一个panic，导致程序崩溃
}

func testc() {
	fmt.Println("cccccccccccccccccc")
}

func main() {
	testa()
	testb(20) //当值是1的时候，就不会越界，值是20的时候，就会越界报错。
	testc()
}
/*
aaaaaaaaaaaaaaaaa
runtime error: index out of range [20] with length 10
cccccccccccccccccc
*/
```



```go
package main

import "fmt"

func f2 () {
	f1 := func(){
		fmt.Println("recover...")
		msg := recover()
		fmt.Println(msg)
	}
	defer f1()
	for i:=0 ;i<=10;i++{
		if i == 5{
			panic("自定义panic")
		}
		fmt.Println(i)
	}
	fmt.Println("end...")
}

func main() {
	fmt.Println("start...") // 正常输出
	f2()    // 报错的执行函数会被终止
	fmt.Println("end...")  // 正常输出
}
```





























